Workbook
Name candidates: candidate!$A$1:$E$2143
Name departments: departments!$A$1:$B$6
Name job_openings: job_openings!$A$1:$F$61

Sheet pivot_hires_by_dept
A3: Row Labels | B3: Count of hire_id
A4: Customer Support | B4: 112
A5: Engineering | B5: 45
A6: Marketing | B6: 19
A7: Operations | B7: 37
A8: Sales | B8: 73
A9: Grand Total | B9: 286

Sheet pivot_time_to_hire
A5: Row Labels | B5: Average of time_to_hire_days
A6: Customer Support | B6: 14.633929
A7: Engineering | B7: 40.2
A8: Marketing | B8: 27.315789
A9: Operations | B9: 27.918919
A10: Sales | B10: 24.643836

Sheet hires
A1: hire_id | B1: candidate_id | C1: hire_date | D1: time_to_hire_days | E1: salary_offered | F1: accepted_offer | G1: opening_id | H1: department_id | I1: department_name | J1: source
A2: 173 | B2: 1237 | C2: 45874 | D2: 26 | E2: 603000 | F2: Yes | G2: =VLOOKUP(B2,candidate!A:E,2,FALSE) -> 32 | H2: =VLOOKUP(G2,job_openings!A:B,2,FALSE) -> 2 | I2: =VLOOKUP(H2,departments!A:B,2,FALSE) -> Sales | J2: =VLOOKUP(B2,candidate!A:E,5,FALSE) -> LinkedIn
A3: 136 | B3: 950 | C3: 45802 | D3: 18 | E3: 384000 | F3: Yes | G3: =VLOOKUP(B3,candidate!A:E,2,FALSE) -> 23 | H3: =VLOOKUP(G3,job_openings!A:B,2,FALSE) -> 3 | I3: =VLOOKUP(H3,departments!A:B,2,FALSE) -> Customer Support | J3: =VLOOKUP(B3,candidate!A:E,5,FALSE) -> LinkedIn | K3: department name | L3: avg_salary
A4: 261 | B4: 1933 | C4: 45975 | D4: 23 | E4: 468000 | F4: Yes | G4: =VLOOKUP(B4,candidate!A:E,2,FALSE) -> 50 | H4: =VLOOKUP(G4,job_openings!A:B,2,FALSE) -> 5 | I4: =VLOOKUP(H4,departments!A:B,2,FALSE) -> Marketing | J4: =VLOOKUP(B4,candidate!A:E,5,FALSE) -> Walk-in | K4: Engineering | L4: =AVERAGEIF(I:I,K4,E:E) -> 983139.53
A5: 142 | B5: 995 | C5: 45818 | D5: 31 | E5: 486277.78 | F5: Yes | G5: =VLOOKUP(B5,candidate!A:E,2,FALSE) -> 25 | H5: =VLOOKUP(G5,job_openings!A:B,2,FALSE) -> 5 | I5: =VLOOKUP(H5,departments!A:B,2,FALSE) -> Marketing | J5: =VLOOKUP(B5,candidate!A:E,5,FALSE) -> LinkedIn | K5: Sales | L5: =AVERAGEIF(I:I,K5,E:E) -> 581986.3
A6: 222 | B6: 1611 | C6: 45948 | D6: 32 | E6: 541000 | F6: Yes | G6: =VLOOKUP(B6,candidate!A:E,2,FALSE) -> 42 | H6: =VLOOKUP(G6,job_openings!A:B,2,FALSE) -> 2 | I6: =VLOOKUP(H6,departments!A:B,2,FALSE) -> Sales | J6: =VLOOKUP(B6,candidate!A:E,5,FALSE) -> Job Board | K6: Customer Support | L6: =AVERAGEIF(I:I,K6,E:E) -> 340765.77
A7: 55 | B7: 415 | C7: 45738 | D7: 26 | E7: 393000 | F7: Yes | G7: =VLOOKUP(B7,candidate!A:E,2,FALSE) -> 10 | H7: =VLOOKUP(G7,job_openings!A:B,2,FALSE) -> 5 | I7: =VLOOKUP(H7,departments!A:B,2,FALSE) -> Marketing | J7: =VLOOKUP(B7,candidate!A:E,5,FALSE) -> Referral | K7: Operations | L7: =AVERAGEIF(I:I,K7,E:E) -> 418810.81
A8: 147 | B8: 1006 | C8: 45864 | D8: 47 | E8: 1118000 | F8: No | G8: =VLOOKUP(B8,candidate!A:E,2,FALSE) -> 26 | H8: =VLOOKUP(G8,job_openings!A:B,2,FALSE) -> 1 | I8: =VLOOKUP(H8,departments!A:B,2,FALSE) -> Engineering | J8: =VLOOKUP(B8,candidate!A:E,5,FALSE) -> Job Board | K8: Marketing | L8: =AVERAGEIF(I:I,K8,E:E) -> 486277.78
A9: 15 | B9: 90 | C9: 45684 | D9: 12 | E9: 346000 | F9: Yes | G9: =VLOOKUP(B9,candidate!A:E,2,FALSE) -> 3 | H9: =VLOOKUP(G9,job_openings!A:B,2,FALSE) -> 3 | I9: =VLOOKUP(H9,departments!A:B,2,FALSE) -> Customer Support | J9: =VLOOKUP(B9,candidate!A:E,5,FALSE) -> Job Board
A10: 112 | B10: 806 | C10: 45783 | D10: 32 | E10: 503000 | F10: Yes | G10: =VLOOKUP(B10,candidate!A:E,2,FALSE) -> 20 | H10: =VLOOKUP(G10,job_openings!A:B,2,FALSE) -> 5 | I10: =VLOOKUP(H10,departments!A:B,2,FALSE) -> Marketing | J10: =VLOOKUP(B10,candidate!A:E,5,FALSE) -> Job Board
A11: 211 | B11: 1541 | C11: 45918 | D11: 34 | E11: 453000 | F11: Yes | G11: =VLOOKUP(B11,candidate!A:E,2,FALSE) -> 39 | H11: =VLOOKUP(G11,job_openings!A:B,2,FALSE) -> 4 | I11: =VLOOKUP(H11,departments!A:B,2,FALSE) -> Operations | J11: =VLOOKUP(B11,candidate!A:E,5,FALSE) -> Referral | M11: source | N11: total _offers | O11: accepted | P11: acceptance_rate_pct
A12: 107 | B12: 740 | C12: 45781 | D12: 6 | E12: 388000 | F12: Yes | G12: =VLOOKUP(B12,candidate!A:E,2,FALSE) -> 18 | H12: =VLOOKUP(G12,job_openings!A:B,2,FALSE) -> 3 | I12: =VLOOKUP(H12,departments!A:B,2,FALSE) -> Customer Support | J12: =VLOOKUP(B12,candidate!A:E,5,FALSE) -> Job Board | M12: Referral | N12: =COUNTIF(J:J,"Referral") -> 86 | O12: =COUNTIFS(J:J,"Referral",F:F,"Yes") -> 82 | P12: =O12/N12*100 -> 95.348837
A13: 138 | B13: 970 | C13: 45821 | D13: 31 | E13: 381000 | F13: Yes | G13: =VLOOKUP(B13,candidate!A:E,2,FALSE) -> 24 | H13: =VLOOKUP(G13,job_openings!A:B,2,FALSE) -> 4 | I13: =VLOOKUP(H13,departments!A:B,2,FALSE) -> Operations | J13: =VLOOKUP(B13,candidate!A:E,5,FALSE) -> Referral | M13: Linkedin | N13: =COUNTIF(J:J,"Linkedin") -> 95 | O13: =COUNTIFS(J:J,"Linkedin",F:F,"Yes") -> 78 | P13: =O13/N13*100 -> 82.105263
A14: 216 | B14: 1581 | C14: 45953 | D14: 43 | E14: 1118000 | F14: Yes | G14: =VLOOKUP(B14,candidate!A:E,2,FALSE) -> 41 | H14: =VLOOKUP(G14,job_openings!A:B,2,FALSE) -> 1 | I14: =VLOOKUP(H14,departments!A:B,2,FALSE) -> Engineering | J14: =VLOOKUP(B14,candidate!A:E,5,FALSE) -> Referral | M14: Job Board | N14: =COUNTIF(J:J,"Job Board") -> 83 | O14: =COUNTIFS(J:J,"Job Board",F:F,"Yes") -> 55 | P14: =O14/N14*100 -> 66.26506
A15: 258 | B15: 1866 | C15: 45952 | D15: 14 | E15: 353000 | F15: Yes | G15: =VLOOKUP(B15,candidate!A:E,2,FALSE) -> 48 | H15: =VLOOKUP(G15,job_openings!A:B,2,FALSE) -> 3 | I15: =VLOOKUP(H15,departments!A:B,2,FALSE) -> Customer Support | J15: =VLOOKUP(B15,candidate!A:E,5,FALSE) -> Referral | M15: Walk-in | N15: =COUNTIF(J:J,"Walk-in") -> 22 | O15: =COUNTIFS(J:J,"Walk-in",F:F,"Yes") -> 14 | P15: =O15/N15*100 -> 63.636364
A16: 229 | B16: 1647 | C16: 45947 | D16: 19 | E16: 320000 | F16: No | G16: =VLOOKUP(B16,candidate!A:E,2,FALSE) -> 43 | H16: =VLOOKUP(G16,job_openings!A:B,2,FALSE) -> 3 | I16: =VLOOKUP(H16,departments!A:B,2,FALSE) -> Customer Support | J16: =VLOOKUP(B16,candidate!A:E,5,FALSE) -> LinkedIn
A17: 214 | B17: 1577 | C17: 45941 | D17: 35 | E17: 906000 | F17: Yes | G17: =VLOOKUP(B17,candidate!A:E,2,FALSE) -> 41 | H17: =VLOOKUP(G17,job_openings!A:B,2,FALSE) -> 1 | I17: =VLOOKUP(H17,departments!A:B,2,FALSE) -> Engineering | J17: =VLOOKUP(B17,candidate!A:E,5,FALSE) -> Referral
A18: 164 | B18: 1177 | C18: 45857 | D18: 44 | E18: 538000 | F18: Yes | G18: =VLOOKUP(B18,candidate!A:E,2,FALSE) -> 30 | H18: =VLOOKUP(G18,job_openings!A:B,2,FALSE) -> 5 | I18: =VLOOKUP(H18,departments!A:B,2,FALSE) -> Marketing | J18: =VLOOKUP(B18,candidate!A:E,5,FALSE) -> Referral
A19: 46 | B19: 340 | C19: 45711 | D19: 9 | E19: 312000 | F19: Yes | G19: =VLOOKUP(B19,candidate!A:E,2,FALSE) -> 8 | H19: =VLOOKUP(G19,job_openings!A:B,2,FALSE) -> 3 | I19: =VLOOKUP(H19,departments!A:B,2,FALSE) -> Customer Support | J19: =VLOOKUP(B19,candidate!A:E,5,FALSE) -> LinkedIn
A20: 224 | B20: 1618 | C20: 45944 | D20: 27 | E20: 684000 | F20: Yes | G20: =VLOOKUP(B20,candidate!A:E,2,FALSE) -> 42 | H20: =VLOOKUP(G20,job_openings!A:B,2,FALSE) -> 2 | I20: =VLOOKUP(H20,departments!A:B,2,FALSE) -> Sales | J20: =VLOOKUP(B20,candidate!A:E,5,FALSE) -> Walk-in
A21: 208 | B21: 1517 | C21: 45922 | D21: 32 | E21: 382000 | F21: Yes | G21: =VLOOKUP(B21,candidate!A:E,2,FALSE) -> 39 | H21: =VLOOKUP(G21,job_openings!A:B,2,FALSE) -> 4 | I21: =VLOOKUP(H21,departments!A:B,2,FALSE) -> Operations | J21: =VLOOKUP(B21,candidate!A:E,5,FALSE) -> Referral
A22: 74 | B22: 519 | C22: 45739 | D22: 22 | E22: 376000 | F22: Yes | G22: =VLOOKUP(B22,candidate!A:E,2,FALSE) -> 13 | H22: =VLOOKUP(G22,job_openings!A:B,2,FALSE) -> 3 | I22: =VLOOKUP(H22,departments!A:B,2,FALSE) -> Customer Support | J22: =VLOOKUP(B22,candidate!A:E,5,FALSE) -> Job Board
A23: 184 | B23: 1302 | C23: 45854 | D23: 15 | E23: 397000 | F23: Yes | G23: =VLOOKUP(B23,candidate!A:E,2,FALSE) -> 33 | H23: =VLOOKUP(G23,job_openings!A:B,2,FALSE) -> 3 | I23: =VLOOKUP(H23,departments!A:B,2,FALSE) -> Customer Support | J23: =VLOOKUP(B23,candidate!A:E,5,FALSE) -> LinkedIn
A24: 246 | B24: 1823 | C24: 45953 | D24: 17 | E24: 515000 | F24: Yes | G24: =VLOOKUP(B24,candidate!A:E,2,FALSE) -> 47 | H24: =VLOOKUP(G24,job_openings!A:B,2,FALSE) -> 2 | I24: =VLOOKUP(H24,departments!A:B,2,FALSE) -> Sales | J24: =VLOOKUP(B24,candidate!A:E,5,FALSE) -> Referral
A25: 239 | B25: 1734 | C25: 45936 | D25: 26 | E25: 421000 | F25: No | G25: =VLOOKUP(B25,candidate!A:E,2,FALSE) -> 44 | H25: =VLOOKUP(G25,job_openings!A:B,2,FALSE) -> 4 | I25: =VLOOKUP(H25,departments!A:B,2,FALSE) -> Operations | J25: =VLOOKUP(B25,candidate!A:E,5,FALSE) -> LinkedIn
A26: 179 | B26: 1281 | C26: 45865 | D26: 12 | E26: 335000 | F26: Yes | G26: =VLOOKUP(B26,candidate!A:E,2,FALSE) -> 33 | H26: =VLOOKUP(G26,job_openings!A:B,2,FALSE) -> 3 | I26: =VLOOKUP(H26,departments!A:B,2,FALSE) -> Customer Support | J26: =VLOOKUP(B26,candidate!A:E,5,FALSE) -> Job Board
A27: 218 | B27: 1591 | C27: 45952 | D27: 36 | E27: 594000 | F27: Yes | G27: =VLOOKUP(B27,candidate!A:E,2,FALSE) -> 42 | H27: =VLOOKUP(G27,job_openings!A:B,2,FALSE) -> 2 | I27: =VLOOKUP(H27,departments!A:B,2,FALSE) -> Sales | J27: =VLOOKUP(B27,candidate!A:E,5,FALSE) -> Referral
... A287: 11 | B287: 56 | C287: 45683 | D287: 18 | E287: 570000 | F287: Yes | G287: =VLOOKUP(B287,candidate!A:E,2,FALSE) -> 2 | H287: =VLOOKUP(G287,job_openings!A:B,2,FALSE) -> 2 | I287: =VLOOKUP(H287,departments!A:B,2,FALSE) -> Sales | J287: =VLOOKUP(B287,candidate!A:E,5,FALSE) -> LinkedIn

Sheet pivot_acceptance_by_source
A8: source | B8: total _offers | C8: accepted | D8: acceptance_rate_pct
A9: Referral | B9: 86 | C9: 82 | D9: 95.3
A10: Linkedin | B10: 95 | C10: 78 | D10: 82.1
A11: Job Board | B11: 83 | C11: 55 | D11: 66.3
A12: Walk-in | B12: 22 | C12: 14 | D12: 63.6

Sheet candidate
A1: candidate_id | B1: opening_id | C1: application_date | D1: stage | E1: source
A2: 354 | B2: 8 | C2: 45690 | D2: Applied | E2: Referral
A3: 273 | B3: 7 | C3: 45698 | D3: Applied | E3: Walk-in
A4: 202 | B4: 4 | C4: 45680 | D4: Rejected | E4: LinkedIn
A5: 1378 | B5: 35 | C5: 45850 | D5: Applied | E5: LinkedIn
A6: 615 | B6: 14 | C6: 45735 | D6: Offered | E6: Referral
A7: 1367 | B7: 34 | C7: 45854 | D7: Rejected | E7: Job Board
A8: 558 | B8: 13 | C8: 45730 | D8: Applied | E8: Referral
A9: 413 | B9: 10 | C9: 45714 | D9: Hired | E9: Referral
A10: 1627 | B10: 42 | C10: 45921 | D10: Interviewed | E10: LinkedIn
A11: 2031 | B11: 53 | C11: 45965 | D11: Interviewed | E11: LinkedIn
A12: 913 | B12: 23 | C12: 45797 | D12: Hired | E12: LinkedIn
A13: 856 | B13: 21 | C13: 15/05/2025 | D13: Interviewed | E13: Job Board
A14: 1452 | B14: 38 | C14: 25/08/2025 | D14: Interviewed | E14: Walk-in
A15: 187 | B15: 4 | C15: 45665 | D15: Hired | E15: Job Board
A16: 2038 | B16: 53 | C16: 45986 | D16: Applied | E16: LinkedIn
A17: 1794 | B17: 46 | C17: 45933 | D17: Applied | E17: Referral
A18: 2106 | B18: 58 | C18: 46005 | D18: Applied | E18: Referral
A19: 1729 | B19: 44 | C19: 45905 | D19: Interviewed | E19: Job Board
A20: 454 | B20: 11 | C20: 45734 | D20: Rejected | E20: Walk-in
A21: 1457 | B21: 38 | C21: 45888 | D21: Applied | E21: Referral
A22: 1190 | B22: 30 | C22: 45831 | D22: Applied | E22: Job Board
A23: 728 | B23: 18 | C23: 22/04/2025 | D23: Hired | E23: LinkedIn
A24: 2040 | B24: 53 | C24: 45966 | D24: Applied | E24: Job Board
A25: 1476 | B25: 38 | C25: 45875 | D25: Applied | E25: LinkedIn
A26: 307 | B26: 7 | C26: 45703 | D26: Interviewed | E26: Job Board
A27: 1712 | B27: 44 | C27: 45914 | D27: Interviewed | E27: LinkedIn
A28: 1617 | B28: 42 | C28: 45901 | D28: Applied | E28: LinkedIn
A29: 676 | B29: 17 | C29: 45767 | D29: Rejected | E29: Walk-in
A30: 1380 | B30: 35 | C30: 45853 | D30: Hired | E30: Job Board
A31: 1236 | B31: 32 | C31: 45860 | D31: Applied | E31: Walk-in
A32: 1198 | B32: 31 | C32: 45848 | D32: Applied | E32: Job Board
A33: 1065 | B33: 27 | C33: 45823 | D33: Applied | E33: Job Board
A34: 1358 | B34: 34 | C34: 45857 | D34: Applied | E34: Job Board
A35: 571 | B35: 13 | C35: 45723 | D35: Hired | E35: Referral
... A153: 49 | B153: 2 | C153: 45680 | D153: Hired | E153: LinkedIn
A154: 1695 | B154: 43 | C154: 15/09/2025 | D154: Interviewed | E154: LinkedIn
A155: 521 | B155: 13 | C155: 45720 | D155: Rejected | E155: LinkedIn
A156: 1230 | B156: 32 | C156: 45854 | D156: Hired | E156: Walk-in
A157: 1648 | B157: 43 | C157: 45916 | D157: Hired | E157: Referral
...

Sheet departments
A1: department_id | B1: department_name
A2: 1 | B2: Engineering
A3: 2 | B3: Sales
A4: 3 | B4: Customer Support
A5: 4 | B5: Operations
A6: 5 | B6: Marketing

Sheet pivot_fill_rate_summary
A1: Row Labels | B1: Sum of target_hires | D1: department_name | E1: total_target | F1: total_hired | G1: fill_rate_pct
A2: 1 | B2: 68 | D2: Engineering | E2: 68 | F2: 45 | G2: =F2/E2*100 -> 66.176471
A3: 2 | B3: 91 | D3: Sales | E3: 91 | F3: 73 | G3: =F3/E3*100 -> 80.21978
A4: 3 | B4: 123 | D4: Customer Support | E4: 123 | F4: 112 | G4: =F4/E4*100 -> 91.056911
A5: 4 | B5: 46 | D5: Operations | E5: 46 | F5: 37 | G5: =F5/E5*100 -> 80.434783
A6: 5 | B6: 33 | D6: Marketing | E6: 33 | F6: 19 | G6: =F6/E6*100 -> 57.575758
A7: Grand Total | B7: 361
F15: i

Sheet job_openings
A1: opening_id | B1: department_id | C1: location | D1: target_hires | E1: month_posted | F1: role_title | G1: location_clean
A2: 1 | B2: 1 | C2: LAGOS | D2: 8 | E2: 2025-01 | F2: QA Engineer | G2: =PROPER(TRIM(C2)) -> Lagos
A3: 2 | B3: 2 | C3: Lagos | D3: 9 | E3: 2025-01 | F3: Business Development Rep | G3: =PROPER(TRIM(C3)) -> Lagos
A4: 3 | B4: 3 | C4: Lagos | D4: 13 | E4: 2025-01 | F4: Support Agent | G4: =PROPER(TRIM(C4)) -> Lagos
A5: 4 | B5: 4 | C5: lagos | D5: 5 | E5: 2025-01 | F5: Logistics Coordinator | G5: =PROPER(TRIM(C5)) -> Lagos
A6: 5 | B6: 5 | C6: Port Harcourt | D6: 3 | E6: 2025-01 | F6: Marketing Executive | G6: =PROPER(TRIM(C6)) -> Port Harcourt
A7: 6 | B7: 1 | C7: Port-Harcourt | D7: 8 | E7: 2025-02 | F7: QA Engineer | G7: =PROPER(TRIM(C7)) -> Port-Harcourt
A8: 7 | B8: 2 | C8: Port Harcourt | D8: 9 | E8: 2025-02 | F8: Sales Executive | G8: =PROPER(TRIM(C8)) -> Port Harcourt
A9: 8 | B9: 3 | C9: Port-Harcourt | D9: 11 | E9: 2025-02 | F9: Customer Success Rep | G9: =PROPER(TRIM(C9)) -> Port-Harcourt
A10: 9 | B10: 4 | C10: IBADAN | D10: 5 | E10: 2025-02 | F10: Operations Analyst | G10: =PROPER(TRIM(C10)) -> Ibadan
A11: 10 | B11: 5 | C11: Ibadan | D11: 4 | E11: 2025-02 | F11: Social Media Manager | G11: =PROPER(TRIM(C11)) -> Ibadan
A12: 11 | B12: 1 | C12: Port Harcourt | D12: 6 | E12: 2025-03 | F12: Software Engineer | G12: =PROPER(TRIM(C12)) -> Port Harcourt
A13: 12 | B13: 2 | C13: abuja | D13: 7 | E13: 2025-03 | F13: Sales Executive | G13: =PROPER(TRIM(C13)) -> Abuja
... A61: 60 | B61: 5 | C61: IBADAN | D61: 1 | E61: 2025-12 | F61: Social Media Manager | G61: =PROPER(TRIM(C61)) -> Ibadan
